[1m[31mERROR   [0m asyncio:base_events.py:1758 Task exception was never retrieved
future: <Task finished name='Task-3661' coro=<Connection.reconnect() done, defined at /home/ubuntu/actions-runner/_work/test-runners-2-is-arm64-postgresql-operator/test-runners-2-is-arm64-postgresql-operator/.tox/integration/lib/python3.10/site-packages/juju/client/connection.py:779> exception=TimeoutError()>
Traceback (most recent call last):
  File "/home/ubuntu/actions-runner/_work/test-runners-2-is-arm64-postgresql-operator/test-runners-2-is-arm64-postgresql-operator/.tox/integration/lib/python3.10/site-packages/websockets/legacy/client.py", line 647, in __await_impl_timeout__
    return await self.__await_impl__()
  File "/home/ubuntu/actions-runner/_work/test-runners-2-is-arm64-postgresql-operator/test-runners-2-is-arm64-postgresql-operator/.tox/integration/lib/python3.10/site-packages/websockets/legacy/client.py", line 651, in __await_impl__
    _transport, _protocol = await self._create_connection()
  File "/usr/lib/python3.10/asyncio/base_events.py", line 1103, in create_connection
    transport, protocol = await self._create_connection_transport(
  File "/usr/lib/python3.10/asyncio/base_events.py", line 1133, in _create_connection_transport
    await waiter
asyncio.exceptions.CancelledError

During handling of the above exception, another exception occurred:

Traceback (most recent call last):
  File "/home/ubuntu/actions-runner/_work/test-runners-2-is-arm64-postgresql-operator/test-runners-2-is-arm64-postgresql-operator/.tox/integration/lib/python3.10/site-packages/juju/client/connection.py", line 788, in reconnect
    res = await connector(
  File "/home/ubuntu/actions-runner/_work/test-runners-2-is-arm64-postgresql-operator/test-runners-2-is-arm64-postgresql-operator/.tox/integration/lib/python3.10/site-packages/juju/client/connection.py", line 868, in _connect_with_login
    await self._connect(endpoints)
  File "/home/ubuntu/actions-runner/_work/test-runners-2-is-arm64-postgresql-operator/test-runners-2-is-arm64-postgresql-operator/.tox/integration/lib/python3.10/site-packages/juju/client/connection.py", line 817, in _connect
    result = await task
  File "/usr/lib/python3.10/asyncio/tasks.py", line 571, in _wait_for_one
    return f.result()  # May raise f.exception().
  File "/home/ubuntu/actions-runner/_work/test-runners-2-is-arm64-postgresql-operator/test-runners-2-is-arm64-postgresql-operator/.tox/integration/lib/python3.10/site-packages/juju/client/connection.py", line 806, in _try_endpoint
    return await self._open(endpoint, cacert)
  File "/home/ubuntu/actions-runner/_work/test-runners-2-is-arm64-postgresql-operator/test-runners-2-is-arm64-postgresql-operator/.tox/integration/lib/python3.10/site-packages/juju/client/connection.py", line 427, in _open
    return (await websockets.connect(
  File "/home/ubuntu/actions-runner/_work/test-runners-2-is-arm64-postgresql-operator/test-runners-2-is-arm64-postgresql-operator/.tox/integration/lib/python3.10/site-packages/websockets/legacy/client.py", line 646, in __await_impl_timeout__
    async with asyncio_timeout(self.open_timeout):
  File "/home/ubuntu/actions-runner/_work/test-runners-2-is-arm64-postgresql-operator/test-runners-2-is-arm64-postgresql-operator/.tox/integration/lib/python3.10/site-packages/websockets/legacy/async_timeout.py", line 169, in __aexit__
    self._do_exit(exc_type)
  File "/home/ubuntu/actions-runner/_work/test-runners-2-is-arm64-postgresql-operator/test-runners-2-is-arm64-postgresql-operator/.tox/integration/lib/python3.10/site-packages/websockets/legacy/async_timeout.py", line 252, in _do_exit
    raise asyncio.TimeoutError
asyncio.exceptions.TimeoutError
[1m[31mERROR   [0m asyncio:base_events.py:1758 Task exception was never retrieved
future: <Task finished name='Task-3662' coro=<Connection.reconnect() done, defined at /home/ubuntu/actions-runner/_work/test-runners-2-is-arm64-postgresql-operator/test-runners-2-is-arm64-postgresql-operator/.tox/integration/lib/python3.10/site-packages/juju/client/connection.py:779> exception=TimeoutError()>
Traceback (most recent call last):
  File "/home/ubuntu/actions-runner/_work/test-runners-2-is-arm64-postgresql-operator/test-runners-2-is-arm64-postgresql-operator/.tox/integration/lib/python3.10/site-packages/websockets/legacy/client.py", line 647, in __await_impl_timeout__
    return await self.__await_impl__()
  File "/home/ubuntu/actions-runner/_work/test-runners-2-is-arm64-postgresql-operator/test-runners-2-is-arm64-postgresql-operator/.tox/integration/lib/python3.10/site-packages/websockets/legacy/client.py", line 651, in __await_impl__
    _transport, _protocol = await self._create_connection()
  File "/usr/lib/python3.10/asyncio/base_events.py", line 1103, in create_connection
    transport, protocol = await self._create_connection_transport(
  File "/usr/lib/python3.10/asyncio/base_events.py", line 1133, in _create_connection_transport
    await waiter
asyncio.exceptions.CancelledError

During handling of the above exception, another exception occurred:

Traceback (most recent call last):
  File "/home/ubuntu/actions-runner/_work/test-runners-2-is-arm64-postgresql-operator/test-runners-2-is-arm64-postgresql-operator/.tox/integration/lib/python3.10/site-packages/juju/client/connection.py", line 788, in reconnect
    res = await connector(
  File "/home/ubuntu/actions-runner/_work/test-runners-2-is-arm64-postgresql-operator/test-runners-2-is-arm64-postgresql-operator/.tox/integration/lib/python3.10/site-packages/juju/client/connection.py", line 868, in _connect_with_login
    await self._connect(endpoints)
  File "/home/ubuntu/actions-runner/_work/test-runners-2-is-arm64-postgresql-operator/test-runners-2-is-arm64-postgresql-operator/.tox/integration/lib/python3.10/site-packages/juju/client/connection.py", line 817, in _connect
    result = await task
  File "/usr/lib/python3.10/asyncio/tasks.py", line 571, in _wait_for_one
    return f.result()  # May raise f.exception().
  File "/home/ubuntu/actions-runner/_work/test-runners-2-is-arm64-postgresql-operator/test-runners-2-is-arm64-postgresql-operator/.tox/integration/lib/python3.10/site-packages/juju/client/connection.py", line 806, in _try_endpoint
    return await self._open(endpoint, cacert)
  File "/home/ubuntu/actions-runner/_work/test-runners-2-is-arm64-postgresql-operator/test-runners-2-is-arm64-postgresql-operator/.tox/integration/lib/python3.10/site-packages/juju/client/connection.py", line 427, in _open
    return (await websockets.connect(
  File "/home/ubuntu/actions-runner/_work/test-runners-2-is-arm64-postgresql-operator/test-runners-2-is-arm64-postgresql-operator/.tox/integration/lib/python3.10/site-packages/websockets/legacy/client.py", line 646, in __await_impl_timeout__
    async with asyncio_timeout(self.open_timeout):
  File "/home/ubuntu/actions-runner/_work/test-runners-2-is-arm64-postgresql-operator/test-runners-2-is-arm64-postgresql-operator/.tox/integration/lib/python3.10/site-packages/websockets/legacy/async_timeout.py", line 169, in __aexit__
    self._do_exit(exc_type)
  File "/home/ubuntu/actions-runner/_work/test-runners-2-is-arm64-postgresql-operator/test-runners-2-is-arm64-postgresql-operator/.tox/integration/lib/python3.10/site-packages/websockets/legacy/async_timeout.py", line 252, in _do_exit
    raise asyncio.TimeoutError
asyncio.exceptions.TimeoutError
[32mINFO    [0m pytest_operator.plugin:plugin.py:862 Model status:

Model  Controller           Cloud/Region         Version  SLA          Timestamp
test   localhost-localhost  localhost/localhost  3.1.8    unsupported  01:53:05Z

App             Version  Status       Scale  Charm       Channel  Rev  Exposed  Message
first-cluster            maintenance      3  postgresql             0  no       installing charm software
second-cluster           maintenance      1  postgresql             1  no       installing PostgreSQL

Unit               Workload     Agent      Machine  Public address  Ports  Message
first-cluster/0*   maintenance  executing  0        10.176.6.26            (install) installing charm software
first-cluster/1    maintenance  executing  1        10.176.6.56            (install) installing PostgreSQL
first-cluster/2    maintenance  executing  2        10.176.6.125           (install) installing charm software
second-cluster/0*  maintenance  executing  3        10.176.6.241           (install) installing PostgreSQL

Machine  State    Address       Inst id        Base          AZ  Message
0        started  10.176.6.26   juju-b7dc2b-0  ubuntu@22.04      Running
1        started  10.176.6.56   juju-b7dc2b-1  ubuntu@22.04      Running
2        started  10.176.6.125  juju-b7dc2b-2  ubuntu@22.04      Running
3        started  10.176.6.241  juju-b7dc2b-3  ubuntu@22.04      Running

[32mINFO    [0m pytest_operator.plugin:plugin.py:868 Juju error logs:

machine-0: 01:47:15 ERROR juju.worker.dependency "broker-tracker" manifold worker returned unexpected error: no container types determined
machine-0: 01:47:15 ERROR juju.worker.dependency "kvm-container-provisioner" manifold worker returned unexpected error: container types not yet available
machine-0: 01:47:15 ERROR juju.worker.dependency "lxd-container-provisioner" manifold worker returned unexpected error: container types not yet available
unit-first-cluster-0: 01:47:15 ERROR juju.worker.meterstatus error running "meter-status-changed": charm missing from disk
machine-2: 01:47:17 ERROR juju.worker.dependency "broker-tracker" manifold worker returned unexpected error: no container types determined
machine-2: 01:47:17 ERROR juju.worker.dependency "lxd-container-provisioner" manifold worker returned unexpected error: container types not yet available
machine-2: 01:47:17 ERROR juju.worker.dependency "kvm-container-provisioner" manifold worker returned unexpected error: container types not yet available
machine-1: 01:47:17 ERROR juju.worker.dependency "lxd-container-provisioner" manifold worker returned unexpected error: container types not yet available
machine-1: 01:47:17 ERROR juju.worker.dependency "kvm-container-provisioner" manifold worker returned unexpected error: container types not yet available
unit-first-cluster-2: 01:47:18 ERROR juju.worker.meterstatus error running "meter-status-changed": charm missing from disk
machine-1: 01:47:18 ERROR juju.worker.dependency "broker-tracker" manifold worker returned unexpected error: no container types determined
unit-first-cluster-1: 01:47:18 ERROR juju.worker.meterstatus error running "meter-status-changed": charm missing from disk
machine-3: 01:47:23 ERROR juju.worker.dependency "kvm-container-provisioner" manifold worker returned unexpected error: container types not yet available
machine-3: 01:47:23 ERROR juju.worker.dependency "broker-tracker" manifold worker returned unexpected error: no container types determined
machine-3: 01:47:23 ERROR juju.worker.dependency "lxd-container-provisioner" manifold worker returned unexpected error: container types not yet available
unit-second-cluster-0: 01:47:24 ERROR juju.worker.meterstatus error running "meter-status-changed": charm missing from disk
machine-0: 01:51:54 ERROR juju.worker.dependency "migration-minion" manifold worker returned unexpected error: connection is shut down
machine-0: 01:51:54 ERROR juju.worker.dependency "api-caller" manifold worker returned unexpected error: api connection broken unexpectedly
machine-0: 01:51:54 ERROR juju.worker.uniter.metrics failed to close the collect-metrics listener: close unix /var/lib/juju/agents/unit-first-cluster-0/973764650/s: use of closed network connection
machine-1: 01:51:58 ERROR juju.worker.dependency "api-caller" manifold worker returned unexpected error: api connection broken unexpectedly
machine-3: 01:51:58 ERROR juju.worker.dependency "api-caller" manifold worker returned unexpected error: api connection broken unexpectedly
machine-2: 01:52:01 ERROR juju.worker.dependency "api-caller" manifold worker returned unexpected error: api connection broken unexpectedly

[32mINFO    [0m pytest_operator.plugin:plugin.py:947 Forgetting model main...