[1m[31mERROR   [0m asyncio:base_events.py:1758 Task exception was never retrieved
future: <Task finished name='Task-1178' coro=<Connection.reconnect() done, defined at /home/ubuntu/actions-runner/_work/test-runners-2-is-arm64-postgresql-operator/test-runners-2-is-arm64-postgresql-operator/.tox/integration/lib/python3.10/site-packages/juju/client/connection.py:779> exception=TimeoutError()>
Traceback (most recent call last):
  File "/home/ubuntu/actions-runner/_work/test-runners-2-is-arm64-postgresql-operator/test-runners-2-is-arm64-postgresql-operator/.tox/integration/lib/python3.10/site-packages/websockets/legacy/client.py", line 647, in __await_impl_timeout__
    return await self.__await_impl__()
  File "/home/ubuntu/actions-runner/_work/test-runners-2-is-arm64-postgresql-operator/test-runners-2-is-arm64-postgresql-operator/.tox/integration/lib/python3.10/site-packages/websockets/legacy/client.py", line 651, in __await_impl__
    _transport, _protocol = await self._create_connection()
  File "/usr/lib/python3.10/asyncio/base_events.py", line 1103, in create_connection
    transport, protocol = await self._create_connection_transport(
  File "/usr/lib/python3.10/asyncio/base_events.py", line 1133, in _create_connection_transport
    await waiter
asyncio.exceptions.CancelledError

During handling of the above exception, another exception occurred:

Traceback (most recent call last):
  File "/home/ubuntu/actions-runner/_work/test-runners-2-is-arm64-postgresql-operator/test-runners-2-is-arm64-postgresql-operator/.tox/integration/lib/python3.10/site-packages/juju/client/connection.py", line 788, in reconnect
    res = await connector(
  File "/home/ubuntu/actions-runner/_work/test-runners-2-is-arm64-postgresql-operator/test-runners-2-is-arm64-postgresql-operator/.tox/integration/lib/python3.10/site-packages/juju/client/connection.py", line 868, in _connect_with_login
    await self._connect(endpoints)
  File "/home/ubuntu/actions-runner/_work/test-runners-2-is-arm64-postgresql-operator/test-runners-2-is-arm64-postgresql-operator/.tox/integration/lib/python3.10/site-packages/juju/client/connection.py", line 817, in _connect
    result = await task
  File "/usr/lib/python3.10/asyncio/tasks.py", line 571, in _wait_for_one
    return f.result()  # May raise f.exception().
  File "/home/ubuntu/actions-runner/_work/test-runners-2-is-arm64-postgresql-operator/test-runners-2-is-arm64-postgresql-operator/.tox/integration/lib/python3.10/site-packages/juju/client/connection.py", line 806, in _try_endpoint
    return await self._open(endpoint, cacert)
  File "/home/ubuntu/actions-runner/_work/test-runners-2-is-arm64-postgresql-operator/test-runners-2-is-arm64-postgresql-operator/.tox/integration/lib/python3.10/site-packages/juju/client/connection.py", line 427, in _open
    return (await websockets.connect(
  File "/home/ubuntu/actions-runner/_work/test-runners-2-is-arm64-postgresql-operator/test-runners-2-is-arm64-postgresql-operator/.tox/integration/lib/python3.10/site-packages/websockets/legacy/client.py", line 646, in __await_impl_timeout__
    async with asyncio_timeout(self.open_timeout):
  File "/home/ubuntu/actions-runner/_work/test-runners-2-is-arm64-postgresql-operator/test-runners-2-is-arm64-postgresql-operator/.tox/integration/lib/python3.10/site-packages/websockets/legacy/async_timeout.py", line 169, in __aexit__
    self._do_exit(exc_type)
  File "/home/ubuntu/actions-runner/_work/test-runners-2-is-arm64-postgresql-operator/test-runners-2-is-arm64-postgresql-operator/.tox/integration/lib/python3.10/site-packages/websockets/legacy/async_timeout.py", line 252, in _do_exit
    raise asyncio.TimeoutError
asyncio.exceptions.TimeoutError
[32mINFO    [0m pytest_operator.plugin:plugin.py:862 Model status:


[32mINFO    [0m pytest_operator.plugin:plugin.py:868 Juju error logs:


[32mINFO    [0m pytest_operator.plugin:plugin.py:947 Forgetting model main...