[32mINFO    [0m pytest_operator.plugin:plugin.py:734 Connecting to existing model localhost-localhost:test on unspecified cloud
[32mINFO    [0m juju.model:model.py:2097 Deploying ch:arm64/jammy/s3-integrator-32
[32mINFO    [0m juju.model:model.py:2097 Deploying ch:arm64/jammy/self-signed-certificates-186
[33mWARNING [0m juju.client.connection:connection.py:578 Receiver: Connection closed, reconnecting
[31m[1mERROR   [0m juju.model:jasyncio.py:53 Task tmp raised an exception: watcher was stopped
Traceback (most recent call last):
  File "/home/ubuntu/actions-runner/_work/test-runners-2-is-arm64-postgresql-operator/test-runners-2-is-arm64-postgresql-operator/.tox/integration/lib/python3.10/site-packages/juju/jasyncio.py", line 41, in _task_result_exp_handler
    task.result()
  File "/home/ubuntu/actions-runner/_work/test-runners-2-is-arm64-postgresql-operator/test-runners-2-is-arm64-postgresql-operator/.tox/integration/lib/python3.10/site-packages/juju/client/facade.py", line 486, in wrapper
    reply = await f(*args, **kwargs)
  File "/home/ubuntu/actions-runner/_work/test-runners-2-is-arm64-postgresql-operator/test-runners-2-is-arm64-postgresql-operator/.tox/integration/lib/python3.10/site-packages/juju/client/_client3.py", line 760, in Next
    reply = await self.rpc(msg)
  File "/home/ubuntu/actions-runner/_work/test-runners-2-is-arm64-postgresql-operator/test-runners-2-is-arm64-postgresql-operator/.tox/integration/lib/python3.10/site-packages/juju/client/overrides.py", line 114, in rpc
    result = await self.connection.rpc(msg, encoder=TypeEncoder)
  File "/home/ubuntu/actions-runner/_work/test-runners-2-is-arm64-postgresql-operator/test-runners-2-is-arm64-postgresql-operator/.tox/integration/lib/python3.10/site-packages/juju/client/connection.py", line 672, in rpc
    raise errors.JujuAPIError(result)
juju.errors.JujuAPIError: watcher was stopped
[33mWARNING [0m juju.model:model.py:1220 Watcher: watcher stopped, restarting
[33mWARNING [0m juju.client.connection:connection.py:654 RPC: Connection closed, reconnecting
[31m[1mERROR   [0m asyncio:base_events.py:1758 Task exception was never retrieved
future: <Task finished name='Task-251' coro=<Connection.reconnect() done, defined at /home/ubuntu/actions-runner/_work/test-runners-2-is-arm64-postgresql-operator/test-runners-2-is-arm64-postgresql-operator/.tox/integration/lib/python3.10/site-packages/juju/client/connection.py:779> exception=InvalidStatusCode(503, Headers([('Content-Type', 'text/plain; charset=utf-8'), ('X-Content-Type-Options', 'nosniff'), ('Date', 'Tue, 03 Sep 2024 03:21:31 GMT'), ('Content-Length', '31')]))>
Traceback (most recent call last):
  File "/home/ubuntu/actions-runner/_work/test-runners-2-is-arm64-postgresql-operator/test-runners-2-is-arm64-postgresql-operator/.tox/integration/lib/python3.10/site-packages/juju/client/connection.py", line 788, in reconnect
    res = await connector(
  File "/home/ubuntu/actions-runner/_work/test-runners-2-is-arm64-postgresql-operator/test-runners-2-is-arm64-postgresql-operator/.tox/integration/lib/python3.10/site-packages/juju/client/connection.py", line 868, in _connect_with_login
    await self._connect(endpoints)
  File "/home/ubuntu/actions-runner/_work/test-runners-2-is-arm64-postgresql-operator/test-runners-2-is-arm64-postgresql-operator/.tox/integration/lib/python3.10/site-packages/juju/client/connection.py", line 817, in _connect
    result = await task
  File "/usr/lib/python3.10/asyncio/tasks.py", line 571, in _wait_for_one
    return f.result()  # May raise f.exception().
  File "/home/ubuntu/actions-runner/_work/test-runners-2-is-arm64-postgresql-operator/test-runners-2-is-arm64-postgresql-operator/.tox/integration/lib/python3.10/site-packages/juju/client/connection.py", line 806, in _try_endpoint
    return await self._open(endpoint, cacert)
  File "/home/ubuntu/actions-runner/_work/test-runners-2-is-arm64-postgresql-operator/test-runners-2-is-arm64-postgresql-operator/.tox/integration/lib/python3.10/site-packages/juju/client/connection.py", line 427, in _open
    return (await websockets.connect(
  File "/home/ubuntu/actions-runner/_work/test-runners-2-is-arm64-postgresql-operator/test-runners-2-is-arm64-postgresql-operator/.tox/integration/lib/python3.10/site-packages/websockets/legacy/client.py", line 647, in __await_impl_timeout__
    return await self.__await_impl__()
  File "/home/ubuntu/actions-runner/_work/test-runners-2-is-arm64-postgresql-operator/test-runners-2-is-arm64-postgresql-operator/.tox/integration/lib/python3.10/site-packages/websockets/legacy/client.py", line 654, in __await_impl__
    await protocol.handshake(
  File "/home/ubuntu/actions-runner/_work/test-runners-2-is-arm64-postgresql-operator/test-runners-2-is-arm64-postgresql-operator/.tox/integration/lib/python3.10/site-packages/websockets/legacy/client.py", line 325, in handshake
    raise InvalidStatusCode(status_code, response_headers)
websockets.exceptions.InvalidStatusCode: server rejected WebSocket connection: HTTP 503
[31m[1mERROR   [0m juju.client.connection:connection.py:662 RPC: Automatic reconnect failed
[31m[1mERROR   [0m asyncio:base_events.py:1758 Task exception was never retrieved
future: <Task finished name='Task-247' coro=<Connection.reconnect() done, defined at /home/ubuntu/actions-runner/_work/test-runners-2-is-arm64-postgresql-operator/test-runners-2-is-arm64-postgresql-operator/.tox/integration/lib/python3.10/site-packages/juju/client/connection.py:779> exception=InvalidStatusCode(503, Headers([('Content-Type', 'text/plain; charset=utf-8'), ('X-Content-Type-Options', 'nosniff'), ('Date', 'Tue, 03 Sep 2024 03:21:31 GMT'), ('Content-Length', '31')]))>
Traceback (most recent call last):
  File "/home/ubuntu/actions-runner/_work/test-runners-2-is-arm64-postgresql-operator/test-runners-2-is-arm64-postgresql-operator/.tox/integration/lib/python3.10/site-packages/juju/client/connection.py", line 788, in reconnect
    res = await connector(
  File "/home/ubuntu/actions-runner/_work/test-runners-2-is-arm64-postgresql-operator/test-runners-2-is-arm64-postgresql-operator/.tox/integration/lib/python3.10/site-packages/juju/client/connection.py", line 868, in _connect_with_login
    await self._connect(endpoints)
  File "/home/ubuntu/actions-runner/_work/test-runners-2-is-arm64-postgresql-operator/test-runners-2-is-arm64-postgresql-operator/.tox/integration/lib/python3.10/site-packages/juju/client/connection.py", line 817, in _connect
    result = await task
  File "/usr/lib/python3.10/asyncio/tasks.py", line 571, in _wait_for_one
    return f.result()  # May raise f.exception().
  File "/home/ubuntu/actions-runner/_work/test-runners-2-is-arm64-postgresql-operator/test-runners-2-is-arm64-postgresql-operator/.tox/integration/lib/python3.10/site-packages/juju/client/connection.py", line 806, in _try_endpoint
    return await self._open(endpoint, cacert)
  File "/home/ubuntu/actions-runner/_work/test-runners-2-is-arm64-postgresql-operator/test-runners-2-is-arm64-postgresql-operator/.tox/integration/lib/python3.10/site-packages/juju/client/connection.py", line 427, in _open
    return (await websockets.connect(
  File "/home/ubuntu/actions-runner/_work/test-runners-2-is-arm64-postgresql-operator/test-runners-2-is-arm64-postgresql-operator/.tox/integration/lib/python3.10/site-packages/websockets/legacy/client.py", line 647, in __await_impl_timeout__
    return await self.__await_impl__()
  File "/home/ubuntu/actions-runner/_work/test-runners-2-is-arm64-postgresql-operator/test-runners-2-is-arm64-postgresql-operator/.tox/integration/lib/python3.10/site-packages/websockets/legacy/client.py", line 654, in __await_impl__
    await protocol.handshake(
  File "/home/ubuntu/actions-runner/_work/test-runners-2-is-arm64-postgresql-operator/test-runners-2-is-arm64-postgresql-operator/.tox/integration/lib/python3.10/site-packages/websockets/legacy/client.py", line 325, in handshake
    raise InvalidStatusCode(status_code, response_headers)
websockets.exceptions.InvalidStatusCode: server rejected WebSocket connection: HTTP 503
[32mINFO    [0m juju.model:model.py:2097 Deploying local:jammy/postgresql-0
[33mWARNING [0m juju.client.connection:connection.py:654 RPC: Connection closed, reconnecting
[31m[1mERROR   [0m juju.client.connection:connection.py:662 RPC: Automatic reconnect failed
[32mINFO    [0m integration.test_backups_pitr:test_backups_pitr.py:78 deleting the previously created backups
[32mINFO    [0m pytest_operator.plugin:plugin.py:862 Model status:

Model  Controller           Cloud/Region         Version  SLA          Timestamp
test   localhost-localhost  localhost/localhost  3.4.4    unsupported  03:22:37Z

App                       Version  Status   Scale  Charm                     Channel        Rev  Exposed  Message
s3-integrator                      waiting    0/1  s3-integrator             latest/stable   32  no       waiting for machine
self-signed-certificates           waiting    0/1  self-signed-certificates  latest/edge    186  no       waiting for machine

Unit                        Workload  Agent       Machine  Public address  Ports  Message
s3-integrator/0             waiting   allocating  0        10.67.93.106           waiting for machine
self-signed-certificates/0  waiting   allocating  1        10.67.93.88            waiting for machine

Machine  State    Address       Inst id        Base          AZ  Message
0        pending  10.67.93.106  juju-28567a-0  ubuntu@22.04      Running
1        pending  10.67.93.88   juju-28567a-1  ubuntu@22.04      Running

[32mINFO    [0m pytest_operator.plugin:plugin.py:868 Juju error logs:


[32mINFO    [0m pytest_operator.plugin:plugin.py:947 Forgetting model main...