[1m[31mERROR   [0m asyncio:base_events.py:1758 Task exception was never retrieved
future: <Task finished name='Task-2088' coro=<Connection.reconnect() done, defined at /home/ubuntu/actions-runner/_work/test-runners-2-is-arm64-postgresql-operator/test-runners-2-is-arm64-postgresql-operator/.tox/integration/lib/python3.10/site-packages/juju/client/connection.py:779> exception=TimeoutError()>
Traceback (most recent call last):
  File "/home/ubuntu/actions-runner/_work/test-runners-2-is-arm64-postgresql-operator/test-runners-2-is-arm64-postgresql-operator/.tox/integration/lib/python3.10/site-packages/websockets/legacy/client.py", line 647, in __await_impl_timeout__
    return await self.__await_impl__()
  File "/home/ubuntu/actions-runner/_work/test-runners-2-is-arm64-postgresql-operator/test-runners-2-is-arm64-postgresql-operator/.tox/integration/lib/python3.10/site-packages/websockets/legacy/client.py", line 651, in __await_impl__
    _transport, _protocol = await self._create_connection()
  File "/usr/lib/python3.10/asyncio/base_events.py", line 1103, in create_connection
    transport, protocol = await self._create_connection_transport(
  File "/usr/lib/python3.10/asyncio/base_events.py", line 1133, in _create_connection_transport
    await waiter
asyncio.exceptions.CancelledError

During handling of the above exception, another exception occurred:

Traceback (most recent call last):
  File "/home/ubuntu/actions-runner/_work/test-runners-2-is-arm64-postgresql-operator/test-runners-2-is-arm64-postgresql-operator/.tox/integration/lib/python3.10/site-packages/juju/client/connection.py", line 788, in reconnect
    res = await connector(
  File "/home/ubuntu/actions-runner/_work/test-runners-2-is-arm64-postgresql-operator/test-runners-2-is-arm64-postgresql-operator/.tox/integration/lib/python3.10/site-packages/juju/client/connection.py", line 868, in _connect_with_login
    await self._connect(endpoints)
  File "/home/ubuntu/actions-runner/_work/test-runners-2-is-arm64-postgresql-operator/test-runners-2-is-arm64-postgresql-operator/.tox/integration/lib/python3.10/site-packages/juju/client/connection.py", line 817, in _connect
    result = await task
  File "/usr/lib/python3.10/asyncio/tasks.py", line 571, in _wait_for_one
    return f.result()  # May raise f.exception().
  File "/home/ubuntu/actions-runner/_work/test-runners-2-is-arm64-postgresql-operator/test-runners-2-is-arm64-postgresql-operator/.tox/integration/lib/python3.10/site-packages/juju/client/connection.py", line 806, in _try_endpoint
    return await self._open(endpoint, cacert)
  File "/home/ubuntu/actions-runner/_work/test-runners-2-is-arm64-postgresql-operator/test-runners-2-is-arm64-postgresql-operator/.tox/integration/lib/python3.10/site-packages/juju/client/connection.py", line 427, in _open
    return (await websockets.connect(
  File "/home/ubuntu/actions-runner/_work/test-runners-2-is-arm64-postgresql-operator/test-runners-2-is-arm64-postgresql-operator/.tox/integration/lib/python3.10/site-packages/websockets/legacy/client.py", line 646, in __await_impl_timeout__
    async with asyncio_timeout(self.open_timeout):
  File "/home/ubuntu/actions-runner/_work/test-runners-2-is-arm64-postgresql-operator/test-runners-2-is-arm64-postgresql-operator/.tox/integration/lib/python3.10/site-packages/websockets/legacy/async_timeout.py", line 169, in __aexit__
    self._do_exit(exc_type)
  File "/home/ubuntu/actions-runner/_work/test-runners-2-is-arm64-postgresql-operator/test-runners-2-is-arm64-postgresql-operator/.tox/integration/lib/python3.10/site-packages/websockets/legacy/async_timeout.py", line 252, in _do_exit
    raise asyncio.TimeoutError
asyncio.exceptions.TimeoutError
[1m[31mERROR   [0m asyncio:base_events.py:1758 Task exception was never retrieved
future: <Task finished name='Task-2089' coro=<Connection.reconnect() done, defined at /home/ubuntu/actions-runner/_work/test-runners-2-is-arm64-postgresql-operator/test-runners-2-is-arm64-postgresql-operator/.tox/integration/lib/python3.10/site-packages/juju/client/connection.py:779> exception=TimeoutError()>
Traceback (most recent call last):
  File "/home/ubuntu/actions-runner/_work/test-runners-2-is-arm64-postgresql-operator/test-runners-2-is-arm64-postgresql-operator/.tox/integration/lib/python3.10/site-packages/websockets/legacy/client.py", line 647, in __await_impl_timeout__
    return await self.__await_impl__()
  File "/home/ubuntu/actions-runner/_work/test-runners-2-is-arm64-postgresql-operator/test-runners-2-is-arm64-postgresql-operator/.tox/integration/lib/python3.10/site-packages/websockets/legacy/client.py", line 651, in __await_impl__
    _transport, _protocol = await self._create_connection()
  File "/usr/lib/python3.10/asyncio/base_events.py", line 1103, in create_connection
    transport, protocol = await self._create_connection_transport(
  File "/usr/lib/python3.10/asyncio/base_events.py", line 1133, in _create_connection_transport
    await waiter
asyncio.exceptions.CancelledError

During handling of the above exception, another exception occurred:

Traceback (most recent call last):
  File "/home/ubuntu/actions-runner/_work/test-runners-2-is-arm64-postgresql-operator/test-runners-2-is-arm64-postgresql-operator/.tox/integration/lib/python3.10/site-packages/juju/client/connection.py", line 788, in reconnect
    res = await connector(
  File "/home/ubuntu/actions-runner/_work/test-runners-2-is-arm64-postgresql-operator/test-runners-2-is-arm64-postgresql-operator/.tox/integration/lib/python3.10/site-packages/juju/client/connection.py", line 868, in _connect_with_login
    await self._connect(endpoints)
  File "/home/ubuntu/actions-runner/_work/test-runners-2-is-arm64-postgresql-operator/test-runners-2-is-arm64-postgresql-operator/.tox/integration/lib/python3.10/site-packages/juju/client/connection.py", line 817, in _connect
    result = await task
  File "/usr/lib/python3.10/asyncio/tasks.py", line 571, in _wait_for_one
    return f.result()  # May raise f.exception().
  File "/home/ubuntu/actions-runner/_work/test-runners-2-is-arm64-postgresql-operator/test-runners-2-is-arm64-postgresql-operator/.tox/integration/lib/python3.10/site-packages/juju/client/connection.py", line 806, in _try_endpoint
    return await self._open(endpoint, cacert)
  File "/home/ubuntu/actions-runner/_work/test-runners-2-is-arm64-postgresql-operator/test-runners-2-is-arm64-postgresql-operator/.tox/integration/lib/python3.10/site-packages/juju/client/connection.py", line 427, in _open
    return (await websockets.connect(
  File "/home/ubuntu/actions-runner/_work/test-runners-2-is-arm64-postgresql-operator/test-runners-2-is-arm64-postgresql-operator/.tox/integration/lib/python3.10/site-packages/websockets/legacy/client.py", line 646, in __await_impl_timeout__
    async with asyncio_timeout(self.open_timeout):
  File "/home/ubuntu/actions-runner/_work/test-runners-2-is-arm64-postgresql-operator/test-runners-2-is-arm64-postgresql-operator/.tox/integration/lib/python3.10/site-packages/websockets/legacy/async_timeout.py", line 169, in __aexit__
    self._do_exit(exc_type)
  File "/home/ubuntu/actions-runner/_work/test-runners-2-is-arm64-postgresql-operator/test-runners-2-is-arm64-postgresql-operator/.tox/integration/lib/python3.10/site-packages/websockets/legacy/async_timeout.py", line 252, in _do_exit
    raise asyncio.TimeoutError
asyncio.exceptions.TimeoutError
[32mINFO    [0m pytest_operator.plugin:plugin.py:862 Model status:

Model  Controller           Cloud/Region         Version  SLA          Timestamp
test   localhost-localhost  localhost/localhost  3.1.8    unsupported  02:18:17Z

App         Version  Status  Scale  Charm       Channel  Rev  Exposed  Message
postgresql  14.11    error       3  postgresql             0  no       hook failed: "restart-relation-changed"

Unit           Workload  Agent      Machine  Public address  Ports     Message
postgresql/0*  waiting   executing  0        10.246.50.178   5432/tcp  awaiting for member to start
postgresql/1   error     idle       1        10.246.50.213   5432/tcp  hook failed: "restart-relation-changed"
postgresql/2   waiting   executing  2        10.246.50.225   5432/tcp  awaiting for cluster to start

Machine  State    Address        Inst id        Base          AZ  Message
0        started  10.246.50.178  juju-7eebaf-0  ubuntu@22.04      Running
1        started  10.246.50.213  juju-7eebaf-1  ubuntu@22.04      Running
2        started  10.246.50.225  juju-7eebaf-2  ubuntu@22.04      Running

[32mINFO    [0m pytest_operator.plugin:plugin.py:868 Juju error logs:

machine-0: 02:10:03 ERROR juju.worker.dependency "lxd-container-provisioner" manifold worker returned unexpected error: container types not yet available
machine-0: 02:10:03 ERROR juju.worker.dependency "broker-tracker" manifold worker returned unexpected error: no container types determined
machine-0: 02:10:03 ERROR juju.worker.dependency "kvm-container-provisioner" manifold worker returned unexpected error: container types not yet available
unit-postgresql-0: 02:10:06 ERROR juju.worker.meterstatus error running "meter-status-changed": charm missing from disk
machine-2: 02:10:22 ERROR juju.worker.dependency "broker-tracker" manifold worker returned unexpected error: no container types determined
machine-2: 02:10:22 ERROR juju.worker.dependency "kvm-container-provisioner" manifold worker returned unexpected error: container types not yet available
machine-2: 02:10:23 ERROR juju.worker.dependency "lxd-container-provisioner" manifold worker returned unexpected error: container types not yet available
unit-postgresql-2: 02:10:26 ERROR juju.worker.meterstatus error running "meter-status-changed": charm missing from disk
machine-1: 02:11:32 ERROR juju.worker.dependency "lxd-container-provisioner" manifold worker returned unexpected error: container types not yet available
machine-1: 02:11:32 ERROR juju.worker.dependency "broker-tracker" manifold worker returned unexpected error: no container types determined
machine-1: 02:11:32 ERROR juju.worker.dependency "kvm-container-provisioner" manifold worker returned unexpected error: container types not yet available
unit-postgresql-1: 02:11:33 ERROR juju.worker.meterstatus error running "meter-status-changed": charm missing from disk
unit-postgresql-1: 02:15:02 ERROR juju.worker.dependency "log-sender" manifold worker returned unexpected error: sending log message: write tcp 10.246.50.213:32980->10.246.50.12:17070: i/o timeout: write tcp 10.246.50.213:32980->10.246.50.12:17070: i/o timeout
unit-postgresql-2: 02:15:14 ERROR juju.worker.dependency "log-sender" manifold worker returned unexpected error: sending log message: websocket: close 1005 (no status): websocket: close sent
unit-postgresql-1: 02:17:37 ERROR juju.worker.dependency "api-caller" manifold worker returned unexpected error: api connection broken unexpectedly
machine-1: 02:17:38 ERROR juju.worker.uniter.metrics failed to close the collect-metrics listener: close unix /var/lib/juju/agents/unit-postgresql-1/4053130983/s: use of closed network connection
machine-1: 02:17:39 ERROR juju.worker.dependency "api-caller" manifold worker returned unexpected error: api connection broken unexpectedly
controller-0: 02:17:41 ERROR juju.worker.cleaner cannot cleanup state: connection is shut down
unit-postgresql-0: 02:18:02 ERROR juju.worker.dependency "log-sender" manifold worker returned unexpected error: sending log message: local error: tls: bad record MAC: use of closed network connection

[32mINFO    [0m pytest_operator.plugin:plugin.py:947 Forgetting model main...